Workbook
Name EF: UUCP!$E$44
Name estimacionEsfuerzo: '[1]Método de Estimación Puntos CU'!$E$50
Name TAW: UUCP!$E$7
Name TBF: UUCP!$E$13
Name TCF: UUCP!$E$32
Name UUCP: UUCP!$E$15

Sheet Costos Indirectos
B1: Costos
B2: Descripción | C2: Anual | D2: Mensual | E2: Costo/empleado | H2: Empleados | I2: 21
B4: Renta | C4: =D4*12 -> 2400000 | D4: 200000 | E4: =+D4/$I$2 -> 9523.8095
B5: Luz | C5: =D5*12 -> 240000 | D5: 20000 | E5: =+D5/$I$2 -> 952.38095
B6: Agua | C6: =D6*12 -> 84000 | D6: 7000 | E6: =+D6/$I$2 -> 333.33333
B7: Internet (Enlaces Dedicados) | C7: =D7*12 -> 360000 | D7: 30000 | E7: =+D7/$I$2 -> 1428.5714
B8: Limpieza | C8: =D8*12 -> 300000 | D8: 25000 | E8: =+D8/$I$2 -> 1190.4762
B9: Papelería | C9: =D9*12 -> 120000 | D9: 10000 | E9: =+D9/$I$2 -> 476.19048
B10: Varios (Mantenimiento site) | C10: =D10*12 -> 360000 | D10: 30000 | E10: =+D10/$I$2 -> 1428.5714
B11: Caja Chica | C11: =D11*12 -> 180000 | D11: 15000 | E11: =+D11/$I$2 -> 714.28571
B19: Total | C19: =SUM(C4:C18) -> 4044000 | D19: =SUM(D4:D18) -> 337000 | E19: =+D19/$I$2 -> 16047.619

Sheet Hw&SW
B1: Infraestructura
B2: Descripción | C2: Número | D2: Costo Unitario | E2: Costo por proyecto | I2: Número de meses de duración | J2: 10
B3: Workstations Gama Alta (Backend / Arquitectura) | C3: 11 | D3: 60000 | E3: =D3*C3 -> 660000 | I3: Empleados proyecto | J3: 21
B4: Laptops Estándar (Analistas, PM) | C4: 10 | D4: 30000 | E4: =D4*C4 -> 300000
B5: Dispositivos Móviles QA | C5: 10 | D5: 20000 | E5: =D5*C5 -> 200000
B6: Escáneres Aulas (Lectores) | C6: 40 | D6: 6000 | E6: =D6*C6 -> 240000
B7: Servidores Físicos (Backup Site) | C7: 1 | D7: 406000 | E7: =D7*C7 -> 406000
B8: AWS / Azure (Mensual x 10) | C8: 1 | D8: 160000 | E8: =D8*C8*J2 -> 1600000
B9: Enterprise Architect | C9: 4 | D9: 8000 | E9: =D9*C9 -> 32000
B10: Licencias IDE (Mensual x 10) | C10: 16 | D10: 1500 | E10: =D10*C10*J2 -> 240000
B11: GitHub Enterprise (Mensual x 10) | C11: 21 | D11: 400 | E11: =D11*C11*J2 -> 84000
B12: Office 365 E5 (Mensual x 10) | C12: 21 | D12: 500 | E12: =D12*C12*J2 -> 105000
B13: Oracle / SQL Server Enterprise | C13: 1 | D13: 600000 | E13: =D13*C13 -> 600000
B16: Totales | E16: =SUM(E3:E15) -> 4467000

Sheet Sueldos
B2: Sueldos
B3: Puesto | C3: Mensual | D3: Recursos Proyecto | E3: Total Mensual | F3: Total Proyecto | G3: Tiempo a Utilizar
B4: Analista (Business Analyst Sr) | C4: 70000 | D4: 3 | E4: =C4*D4 -> 210000 | F4: =E4*G4 -> 1260000 | G4: 6
B5: Diseñador (UX/UI y Service Design) | C5: 65000 | D5: 1 | E5: =C5*D5 -> 65000 | F5: =E5*G5 -> 390000 | G5: 6
B6: Arquitecto SW (Cloud Architect) | C6: 90000 | D6: 1 | E6: =C6*D6 -> 90000 | F6: =E6*G6 -> 900000 | G6: 10
B7: Programador (Fullstack/Mobile Sr) | C7: 90000 | D7: 8 | E7: =C7*D7 -> 720000 | F7: =E7*G7 -> 5760000 | G7: 8
B8: Tester (QA Automation Engineer) | C8: 70000 | D8: 5 | E8: =C8*D8 -> 350000 | F8: =E8*G8 -> 2800000 | G8: 8
B9: Dirección Proyecto (Project Director) | C9: 140000 | D9: 1 | E9: =C9*D9 -> 140000 | F9: =E9*G9 -> 1400000 | G9: 10
B10: Scrum Master (Agile Coach) | C10: 70000 | D10: 0 | E10: =C10*D10 -> 0 | F10: =E10*G10 -> 0
B11: Implementador (DevOps/SecOps) | C11: 85000 | D11: 1 | E11: =C11*D11 -> 85000 | F11: =E11*G11 -> 850000 | G11: 10
B12: Change Management (Líder Capacitación) | C12: 45000 | D12: 0 | E12: =C12*D12 -> 0 | F12: =E12*G12 -> 0
B13: DBA (Data Engineer Sr) | C13: 90000 | D13: 1 | E13: =C13*D13 -> 90000 | F13: =E13*G13 -> 720000 | G13: 8
B18: Totales | D18: =SUM(D4:D17) -> 21 | E18: =SUM(E4:E17) -> 1750000 | F18: =SUM(F4:F17) -> 14080000

Sheet Otros
B2: Otros Costos
B3: Descripción | C3: Nùmero | D3: Costo | E3: Total
B4: Viajes corporativos (España) | C4: 6 | D4: 150000 | E4: =+D4*C4 -> 900000
B5: Campaña Marketing | C5: 1 | D5: 1000000 | E5: =+D5*C5 -> 1000000
B6: Auditoría Ciberseguridad | C6: 1 | D6: 500000 | E6: =+D6*C6 -> 500000
B7: Viáticos sucursales CDMX | C7: 40 | D7: 10000 | E7: =+D7*C7 -> 400000
B8: Servicios Legales | C8: 1 | D8: 700000 | E8: =+D8*C8 -> 700000
B9: Certificaciones Técnicas | C9: 8 | D9: 60000 | E9: =+D9*C9 -> 480000
B10: Totales | E10: =SUM(E4:E9) -> 3980000

Sheet TotalProyecto
B2: Resumen Costos
B3: Descripciòn | C3: Costo | D3: % | E3: Tiempo
B4: Indirectos | C4: =+'Costos Indirectos'!E19*'Hw&SW'!J3*'Hw&SW'!J2 -> 3370000
B5: Infraestructura | C5: =+'Hw&SW'!E16 -> 4467000
B6: Sueldos | C6: =+Sueldos!F18 -> 14080000
B7: Otros | C7: =+Otros!E10 -> 3980000
B8: Total Proyecto | C8: =SUM(C4:C6) -> 21917000
B9: Ganancia | C9: =B15-C8 -> 11877760 | D9: =C9/B15 -> 0.35146751
B10: Total Propuesto | C10: =+C9+C8 -> 33794760 | E10: =+DistribuciónEsfuerzo!C23 -> 7.5345655
B13: Presupuesto | C13: Tiempo
B14: 2,000,000 USD | C14: 10
B15: 33794760

Sheet UUCP
A1: ESTIMACIÓN DE ESFUERZO
A3: Factor de Peso Actores | B3: Descripción | C3: Peso | D3: Número | E3: Valor ponderado | F3: Comentario
A4: Simple | B4: API Programa | C4: 1 | D4: 2 | E4: =C4*D4 -> 2
A5: Intermedio | B5: WS | C5: 2 | D5: 3 | E5: =C5*D5 -> 6
A6: Complejo | B6: Humano con GUI | C6: 3 | D6: 5 | E6: =C6*D6 -> 15
A7: Peso Total Actores | E7: =SUM(E4:E6) -> 23
A9: Factor de Peso Casos de Uso (Basado en el número de transacciones en el CU) | C9: Peso | D9: Número | E9: Valor ponderado | F9: Comentario
A10: Simple | B10: 3 ó menos escenarios | C10: 5 | D10: 1 | E10: =C10*D10 -> 5
A11: Intermedio | B11: 4 a 7 escenarios | C11: 10 | D11: 9 | E11: =C11*D11 -> 90
A12: Complejo | B12: más de 7 escenarios | C12: 15 | D12: 0 | E12: =C12*D12 -> 0
A13: Factores Basados en Transacciones | E13: =SUM(E10:E12) -> 95
A15: Puntos de CU No Ajustados | E15: =TAW+TBF -> 118
A17: Factores de Peso Técnicos | B17: Escala de asignación | C17: Peso | D17: Número | E17: Valor ponderado | F17: Razón
A18: T1 Sistema Distribuido | B18: 0=no importante 5=esencial | C18: 2 | D18: 5 | E18: =C18*D18 -> 10
A19: T2 Objetivos de Desempeño o Tiempo de Respuesta | B19: 0=no importante 5=esencial | C19: 1 | D19: 4 | E19: =C19*D19 -> 4
A20: T3 Eficiencia Usuario Final (online) | B20: 0=no importante 5=esencial | C20: 1 | D20: 5 | E20: =C20*D20 -> 5
A21: T4 Procesamiento Interno Complejo | B21: 0=no importante 5=esencial | C21: 1 | D21: 4 | E21: =C21*D21 -> 4
A22: T5 Código Debe Ser Reusable | B22: 0=no importante 5=esencial | C22: 1 | D22: 5 | E22: =C22*D22 -> 5
A23: T6 Facilidad de Instalación | B23: 0=no importante 5=esencial | C23: 0.5 | D23: 3 | E23: =C23*D23 -> 1.5
A24: T7 Facilidad de Uso | B24: 0=no importante 5=esencial | C24: 0.5 | D24: 5 | E24: =C24*D24 -> 2.5
A25: T8 Portabilidad | B25: 0=no importante 5=esencial | C25: 2 | D25: 4 | E25: =C25*D25 -> 8
A26: T9 Facilidad de Cambio | B26: 0=no importante 5=esencial | C26: 1 | D26: 5 | E26: =C26*D26 -> 5
A27: T10 Concurrencia | B27: 0=no importante 5=esencial | C27: 1 | D27: 5 | E27: =C27*D27 -> 5
A28: T11 Incluye Características Especiales de Seguridad | B28: 0=no importante 5=esencial | C28: 1 | D28: 5 | E28: =C28*D28 -> 5
A29: T12 Provee Acceso Directo a Terceros | B29: 0=no importante 5=esencial | C29: 1 | D29: 5 | E29: =C29*D29 -> 5
A30: T13 Se Requieren Ayudas Especiales de Entrenamiento de Usuarios | B30: 0=no importante 5=esencial | C30: 1 | D30: 0 | E30: =C30*D30 -> 0
A31: Factores Técnicos | E31: =SUM(E18:E30) -> 60
A32: Factor de Complejidad Técnica (TCF) | B32: .06 + (.01*Factor Técnico) | E32: =0.01*E31+0.06 -> 0.66
A34: Factores de Peso Ambientales del Equipo | B34: Escala de 0 a 5 | C34: Peso | D34: Número | E34: Valor ponderado | F34: Razón | G34: Experiencia/Estabilidad
A35: F1 Familiaridad con un Proceso Definido (RUP) | B35: 0 = sin experiencia, 3=media, 5=experto | C35: 1.5 | D35: 3 | E35: =C35*D35 -> 4.5 | G35: =IF(E35<3,1,0) -> 0
A36: F2 Experiencia en el Dominio de Aplicación | B36: 0 = sin experiencia, 3=media, 5=experto | C36: 0.5 | D36: 3 | E36: =C36*D36 -> 1.5 | G36: =IF(E36<3,1,0) -> 1
A37: F3 Experiencia en Orientación a Objetos | B37: 0 = sin experiencia, 3=media, 5=experto | C37: 1 | D37: 2 | E37: =C37*D37 -> 2 | G37: =IF(E37<3,1,0) -> 1
A38: F4 Capacidad de Liderazgo de Analistas | B38: 0 = sin experiencia, 3=media, 5=experto | C38: 0.5 | D38: 4 | E38: =C38*D38 -> 2 | G38: =IF(E38<3,1,0) -> 1
A39: F5 Motivación | B39: 0=sin, 3=media, 5=alta | C39: 1 | D39: 5 | E39: =C39*D39 -> 5 | G39: =IF(E39<3,1,0) -> 0
A40: F6 Requerimientos Estables | B40: 0=extremadamente inestable, 5=no cambian | C40: 2 | D40: 2 | E40: =C40*D40 -> 4 | G40: =IF(E40<3,1,0) -> 0
A41: F7 Miembros a Tiempo Parcial | B41: 0=tiempo parcial, 5=tiempo completo | C41: -1 | D41: 5 | E41: =C41*D41 -> -5 | G41: =IF(E41>3,1,0) -> 0
A42: F8 Dificultad del Lenguaje de Programación | B42: 0=fácil, 3=medio,5=difícil | C42: -1 | D42: 3 | E42: =C42*D42 -> -3 | G42: =IF(E42>3,1,0) -> 0
A43: Factores Ambientales | E43: =SUM(E35:E42) -> 11 | G43: =SUM(G35:G42) -> 3
A44: EFactor | B44: 1.4 + (-0.03*Factor Ambiental) | E44: =1.4 + (-0.03*E43) -> 1.07
A46: Puntos de Casos de Uso Ajustados | E46: =UUCP * TCF *EF -> 83.3316
...

Sheet DistribuciónEsfuerzo
A1: Distribución de esfuerzo
A2: Etapa | B2: Ponderación | C2: Horas Hombre | E2: Horas Hombre Totales | F2: Horas Mes | G2: Meses | H2: Personas En Equipo | I2: Total Meses
A3: Análisis | B3: 0.25 | C3: =+C7*B3 -> 1166.6424 | E3: =+$C$7 -> 4666.5696 | F3: 160 | G3: =+E3/F3 -> 29.16606 | H3: 2 | I3: =+G3/H3 -> 14.58303
A4: Diseño | B4: 0.2 | C4: =+C7*B4 -> 933.31392 | E4: =+$C$7 -> 4666.5696 | F4: 160 | G4: =+E4/F4 -> 29.16606 | H4: 3 | I4: =+G4/H4 -> 9.72202
A5: Programación | B5: 0.35 | C5: =+C7*B5 -> 1633.2994 | E5: =+$C$7 -> 4666.5696 | F5: 160 | G5: =+E5/F5 -> 29.16606 | H5: 4 | I5: =+G5/H5 -> 7.291515
A6: Test | B6: 0.2 | C6: =+C7*B6 -> 933.31392 | E6: =+$C$7 -> 4666.5696 | F6: 160 | G6: =+E6/F6 -> 29.16606 | H6: 5 | I6: =+G6/H6 -> 5.833212
A7: Total | B7: =SUM(B3:B6) -> 1 | C7: =+UUCP!E50 -> 4666.5696 | E7: =+$C$7 -> 4666.5696 | F7: 160 | G7: =+E7/F7 -> 29.16606 | H7: 6 | I7: =+G7/H7 -> 4.86101
E8: =+$C$7 -> 4666.5696 | F8: 160 | G8: =+E8/F8 -> 29.16606 | H8: 7 | I8: =+G8/H8 -> 4.16658
A9: Costo | E9: =+$C$7 -> 4666.5696 | F9: 160 | G9: =+E9/F9 -> 29.16606 | H9: 8 | I9: =+G9/H9 -> 3.6457575
A10: Etapa | B10: Sueldo | E10: =+$C$7 -> 4666.5696 | F10: 160 | G10: =+E10/F10 -> 29.16606 | H10: 9 | I10: =+G10/H10 -> 3.2406733
A11: Análisis | B11: =+K16 -> 510406.05
A12: Diseño | B12: =+K28 -> 379158.78
A13: Programación | B13: =+K39 -> 918730.89 | E13: Análisis
A14: Test | B14: =+K54 -> 408324.84 | E14: Horas Hombre Totales | F14: Horas Mes | G14: Meses | H14: Personas En Equipo | I14: Total Meses | J14: Costo Analista | K14: Costo Total
A15: Total | B15: =SUM(B11:B14) -> 2216620.6 | E15: =+$C$3 -> 1166.6424 | F15: 160 | G15: =+E15/F15 -> 7.291515 | H15: 1 | I15: =+G15/H15 -> 7.291515 | J15: 70000 | K15: =+J15*H15*I15 -> 510406.05
E16: =+$C$3 -> 1166.6424 | F16: 160 | G16: =+E16/F16 -> 7.291515 | H16: 2 | I16: =+G16/H16 -> 3.6457575 | J16: 70000 | K16: =+J16*H16*I16 -> 510406.05
A17: Recursos | E17: =+$C$3 -> 1166.6424 | F17: 160 | G17: =+E17/F17 -> 7.291515 | H17: 3 | I17: =+G17/H17 -> 2.430505 | J17: 70000 | K17: =+J17*H17*I17 -> 510406.05
A18: Etapa | B18: Número | C18: Tiempo | E18: =+$C$3 -> 1166.6424 | F18: 160 | G18: =+E18/F18 -> 7.291515 | H18: 4 | I18: =+G18/H18 -> 1.8228787 | J18: 70000 | K18: =+J18*H18*I18 -> 510406.05
A19: Análisis | B19: =+H17 -> 3 | C19: =+I17 -> 2.430505 | E19: =+$C$3 -> 1166.6424 | F19: 160 | G19: =+E19/F19 -> 7.291515 | H19: 5 | I19: =+G19/H19 -> 1.458303 | J19: 70000 | K19: =+J19*H19*I19 -> 510406.05
A20: Diseño | B20: =+H28 -> 2 | C20: =+I28 -> 2.916606 | E20: =+$C$3 -> 1166.6424 | F20: 160 | G20: =+E20/F20 -> 7.291515 | H20: 6 | I20: =+G20/H20 -> 1.2152525 | J20: 70000 | K20: =+J20*H20*I20 -> 510406.05
A21: Programación | B21: =+H47 -> 10 | C21: =+I47 -> 1.0208121 | E21: =+$C$3 -> 1166.6424 | F21: 160 | G21: =+E21/F21 -> 7.291515 | H21: 7 | I21: =+G21/H21 -> 1.041645 | J21: 70000 | K21: =+J21*H21*I21 -> 510406.05
A22: Test | B22: =+H57 -> 5 | C22: =+I57 -> 1.1666424 | E22: =+$C$3 -> 1166.6424 | F22: 160 | G22: =+E22/F22 -> 7.291515 | H22: 8 | I22: =+G22/H22 -> 0.91143937 | J22: 70000 | K22: =+J22*H22*I22 -> 510406.05
A23: Total | B23: =SUM(B19:B22) -> 20 | C23: =SUM(C19:C22) -> 7.5345655 | E23: =+$C$3 -> 1166.6424 | F23: 160 | G23: =+E23/F23 -> 7.291515 | H23: 9 | I23: =+G23/H23 -> 0.81016833 | J23: 70000 | K23: =+J23*H23*I23 -> 510406.05
E25: Diseño
E26: Horas Hombre Totales | F26: Horas Mes | G26: Meses | H26: Personas En Equipo | I26: Total Meses | J26: Costo Diseñador | K26: Costo Total
E27: =+$C$4 -> 933.31392 | F27: 160 | G27: =+E27/F27 -> 5.833212 | H27: 1 | I27: =+G27/H27 -> 5.833212 | J27: 65000 | K27: =+J27*H27*I27 -> 379158.78
E28: =+$C$4 -> 933.31392 | F28: 160 | G28: =+E28/F28 -> 5.833212 | H28: 2 | I28: =+G28/H28 -> 2.916606 | J28: 65000 | K28: =+J28*H28*I28 -> 379158.78
E29: =+$C$4 -> 933.31392 | F29: 160 | G29: =+E29/F29 -> 5.833212 | H29: 3 | I29: =+G29/H29 -> 1.944404 | J29: 65000 | K29: =+J29*H29*I29 -> 379158.78
E30: =+$C$4 -> 933.31392 | F30: 160 | G30: =+E30/F30 -> 5.833212 | H30: 4 | I30: =+G30/H30 -> 1.458303 | J30: 65000 | K30: =+J30*H30*I30 -> 379158.78
E31: =+$C$4 -> 933.31392 | F31: 160 | G31: =+E31/F31 -> 5.833212 | H31: 5 | I31: =+G31/H31 -> 1.1666424 | J31: 65000 | K31: =+J31*H31*I31 -> 379158.78
E32: =+$C$4 -> 933.31392 | F32: 160 | G32: =+E32/F32 -> 5.833212 | H32: 6 | I32: =+G32/H32 -> 0.972202 | J32: 65000 | K32: =+J32*H32*I32 -> 379158.78
E33: =+$C$4 -> 933.31392 | F33: 160 | G33: =+E33/F33 -> 5.833212 | H33: 7 | I33: =+G33/H33 -> 0.833316 | J33: 65000 | K33: =+J33*H33*I33 -> 379158.78
E34: =+$C$4 -> 933.31392 | F34: 160 | G34: =+E34/F34 -> 5.833212 | H34: 8 | I34: =+G34/H34 -> 0.7291515 | J34: 65000 | K34: =+J34*H34*I34 -> 379158.78
E35: =+$C$4 -> 933.31392 | F35: 160 | G35: =+E35/F35 -> 5.833212 | H35: 9 | I35: =+G35/H35 -> 0.64813467 | J35: 65000 | K35: =+J35*H35*I35 -> 379158.78
E37: Programación
E38: Horas Hombre Totales | F38: Horas Mes | G38: Meses | H38: Personas En Equipo | I38: Total Meses | J38: Costo Programador | K38: Costo Total
E39: =+$C$5 -> 1633.2994 | F39: 160 | G39: =+E39/F39 -> 10.208121 | H39: 2 | I39: =+G39/H39 -> 5.1040605 | J39: 90000 | K39: =+J39*H39*I39 -> 918730.89
E40: =+$C$5 -> 1633.2994 | F40: 160 | G40: =+E40/F40 -> 10.208121 | H40: 3 | I40: =+G40/H40 -> 3.402707 | J40: 90000 | K40: =+J40*H40*I40 -> 918730.89
E41: =+$C$5 -> 1633.2994 | F41: 160 | G41: =+E41/F41 -> 10.208121 | H41: 4 | I41: =+G41/H41 -> 2.5520302 | J41: 90000 | K41: =+J41*H41*I41 -> 918730.89
E42: =+$C$5 -> 1633.2994 | F42: 160 | G42: =+E42/F42 -> 10.208121 | H42: 5 | I42: =+G42/H42 -> 2.0416242 | J42: 90000 | K42: =+J42*H42*I42 -> 918730.89
...
